# .send()

Метод `send()` используется для отправки значения в активный генератор.

- Возобновляет выполнение генератора, передавая указанное значение в текущую точку `yield`.
- Возвращает следующее значение, которое генератор `yield` после возобновления.

```pycon
>>> def echo():
...     while True:
...         received = yield
...         print(f"Received: {received}")
...
>>> gen = echo()
>>> # Запускаем генератор до первого yield
>>> next(gen)
>>> gen.send("Hello")
Received: Hello
>>> gen.send("World")
Received: World
```

```pycon
>>> def accumulator():
...     total = 0
...     while True:
...         # Возвращаем текущую сумму
...         value = yield total
...         # Если ничего не передали, пропускаем
...         if value is None:
...             continue
...         # Добавляем переданное значение
...         total += value
...
>>> gen = accumulator()
>>> # Запускаем генератор, начальная сумма = 0
>>> print(next(gen))
0
>>> # Добавляем 10, сумма = 10
>>> print(gen.send(10))
10
>>> print(gen.send(20))
30
>>> print(gen.send(0))
30
>>> print(next(gen))
30
```

```pycon
>>> def controlled_count():
...     count = 0
...     while True:
...         command = yield count
...         if command == "stop":
...             break
...         elif command == "reset":
...             count = 0
...         else:
...             count += 1
...
>>> gen = controlled_count()
>>> # Начало, count = 0
>>> print(next(gen))
0
>>> print(gen.send(None))
1
>>> print(gen.send(None))
2
>>> print(gen.send("reset"))
0
>>> print(gen.send(None))
1
>>> gen.send("stop")
Traceback (most recent call last):
  File "<stdin>", line 1, in <module>
StopIteration
```

## Примечания
- **`.send(None)` аналогично `next()`**:
    - Используется для первого вызова генератора или продолжения без передачи данных.
    - При первом вызове генератор должен быть готов принять `None`, иначе возникнет ошибка `TypeError`. ```pycon
>>> gen = accumulator()
>>> gen.send(None)
0
>>> gen = accumulator()
>>> gen.send(1)
Traceback (most recent call last):
  File "<stdin>", line 1, in <module>
TypeError: can't send non-None value to a just-started generator
```
- Исключение при остановке генератора:
    - Если генератор завершил выполнение `StopIteration`, вызов `.send()` приводит к выбросу исключения.
- Использование с корутинами:
    - Метод `.send()` часто применяется в сопрограммах на основе генераторов для обмена данными между частями кода.


# .throw(type, value=None, traceback=None)

Генератору передается исключение.
Оно выбрасывается в текущей точке `yield`, где его можно обработать с помощью `try-except`.

```pycon
>>> def example():
...     try:
...         yield
...     except ValueError as e:
...         yield f"Caught: {e}"
...
>>> gen = example()
>>> next(gen)
>>> print(gen.throw(ValueError, "Test"))
Caught: Test
```

# .close()

Завершает генератор.
Если генератор ожидает на `yield`, он выбрасывает исключение `GeneratorExit`.
Используется для принудительного завершения работы генератора.

```pycon
>>> def example():
...     try:
...         yield
...     except GeneratorExit:
...         print("Generator closed!")
...
>>> gen = example()
>>> next(gen)
>>> gen.close()
Generator closed!
```
